import time
import pytest
from unittest.mock import patch, Mock
from hyperon_das.exceptions import ConnectionServerException, RetryException
from hyperon_das.decorators import retry

logger_mock = Mock()


@patch('hyperon_das.logger')
def test_retry_successful_connection(logger_mock):
    expected_output = "Success"

    @retry(attempts=3, timeout_seconds=5)
    def successful_function(self, host, port):
        return expected_output

    result = successful_function({}, 'localhost', 80)

    assert result == expected_output


@patch('hyperon_das.logger')
def test_retry_exception_raised(logger_mock):
    @retry(attempts=3, timeout_seconds=5)
    def exception_function():
        raise ValueError("Simulated exception")

    with pytest.raises(
        ConnectionServerException, match='An error occurs while connecting to the server'
    ):
        exception_function()
